<?xml version="1.0"?>
<sdf version="1.6">
  <model name="my_lrauv">
    <!-- Body -->
    <link name="base_link">
      <inertial>
        <mass>147.8671</mass>
        <inertia>
          <ixx>3.000000</ixx>
          <ixy>0</ixy>
          <ixz>0</ixz>
          <iyy>41.980233</iyy>
          <iyz>0</iyz>
          <izz>41.980233</izz>
        </inertia>
      </inertial>
      <!-- Uncomment this block to enable neutral buoyancy. -->
      <collision name="main_body_buoyancy">
        <geometry>
          <box>
            <size>2 0.3 0.2464451666666667</size>
          </box>
        </geometry>
      </collision>
      <visual name="visual">
        <geometry>
          <mesh>
            <uri>meshes/tethys.dae</uri>
            <submesh>
              <name>Body</name>
                <center>false</center>
            </submesh>
          </mesh>
        </geometry>
        <material>
          <diffuse>1.0 1.0 1.0</diffuse>
          <specular>1.0 1.0 1.0</specular>
          <pbr>
            <metal>
              <albedo_map>materials/textures/Tethys_Albedo.png</albedo_map>
              <normal_map>materials/textures/Tethys_Normal.png</normal_map>
              <metalness_map>materials/textures/Tethys_Metalness.png</metalness_map>
              <roughness_map>materials/textures/Tethys_Roughness.png</roughness_map>
            </metal>
          </pbr>
        </material>
      </visual>
    </link>
    <!-- Horizontal fins -->
    <link name="horizontal_fins">
      <pose>1.05 0 0 0 0 0</pose>
      <inertial>
        <pose>0 0 0 1.57 0 0.5</pose>
        <mass>0.2</mass>
        <inertia>
          <ixx>0.0007924568755</ixx>
          <ixy>-0.0000000002674</ixy>
          <ixz>0.0003978158176</ixz>
          <iyy>0.0010546736475</iyy>
          <iyz>-0.0000000006729</iyz>
          <izz>0.0002633558262</izz>
         </inertia>
      </inertial>
      <collision name="collision">
        <geometry>
          <box>
            <size>0.1 0.1 0.02</size>
          </box>
        </geometry>
      </collision>
      <visual name="visual">
        <pose>-1.05 0 0 0 0 0</pose>
        <geometry>
          <mesh>
            <uri>meshes/tethys.dae</uri>
            <submesh>
              <name>Fins_Horizontal</name>
              <center>false</center>
            </submesh>
          </mesh>
        </geometry>
        <material>
          <diffuse>1.0 1.0 1.0</diffuse>
          <specular>1.0 1.0 1.0</specular>
          <pbr>
            <metal>
              <albedo_map>materials/textures/Tethys_Albedo.png</albedo_map>
              <normal_map>materials/textures/Tethys_Normal.png</normal_map>
              <metalness_map>materials/textures/Tethys_Metalness.png</metalness_map>
              <roughness_map>materials/textures/Tethys_Roughness.png</roughness_map>
            </metal>
          </pbr>
        </material>
        </visual>
    </link>
    <!-- Vertical fins -->
    <link name="vertical_fins">
      <pose>1.05 0 0 0 0 0</pose>
      <inertial>
        <mass>0.2</mass>
        <inertia>
          <ixx>0.0007924568755</ixx>
          <ixy>-0.0000000002674</ixy>
          <ixz>0.0003978158176</ixz>
          <iyy>0.0010546736475</iyy>
          <iyz>-0.0000000006729</iyz>
          <izz>0.0002633558262</izz>
        </inertia>
      </inertial>
      <collision name="collision">
        <geometry>
          <box>
            <size>0.1 0.1 0.02</size>
          </box>
        </geometry>
      </collision>
      <visual name="visual">
        <pose>-1.05 0 0 0 0 0</pose>
        <geometry>
          <mesh>
            <uri>meshes/tethys.dae</uri>
            <submesh>
              <name>Fins_vertical</name>
              <center>false</center>
            </submesh>
          </mesh>
        </geometry>
        <material>
          <diffuse>1.0 1.0 1.0</diffuse>
          <specular>1.0 1.0 1.0</specular>
          <pbr>
            <metal>
              <albedo_map>materials/textures/Tethys_Albedo.png</albedo_map>
              <normal_map>materials/textures/Tethys_Normal.png</normal_map>
              <metalness_map>materials/textures/Tethys_Metalness.png</metalness_map>
              <roughness_map>materials/textures/Tethys_Roughness.png</roughness_map>
            </metal>
          </pbr>
        </material>
      </visual>
    </link>
    <!-- Propeller -->
    <link name="propeller">
      <pose>1.43162 0 0 0 0 0</pose>
      <inertial>
        <pose>0 0 0 0 0 0</pose>
        <mass>0.09</mass>
        <inertia>
          <ixx>0.000143971303</ixx>
          <ixy>0.000000000008</ixy>
          <ixz>-0.000000000224</ixz>
          <iyy>0.000140915448</iyy>
          <iyz>-0.000025236433</iyz>
          <izz>0.000033571862</izz>
        </inertia>
      </inertial>
      <collision name="collision">
        <geometry>
          <box>
            <size>0.03 0.1 0.03</size>
          </box>
        </geometry>
      </collision>
      <visual name="visual">
        <pose>-1.43162 0 0 0 0 0</pose>
        <geometry>
          <mesh>
            <uri>meshes/tethys.dae</uri>
            <submesh>
              <name>Prop</name>
              <center>false</center>
            </submesh>
          </mesh>
        </geometry>
        <material>
          <diffuse>1.0 1.0 1.0</diffuse>
          <specular>1.0 1.0 1.0</specular>
          <pbr>
            <metal>
              <albedo_map>materials/textures/Tethys_Albedo.png</albedo_map>
              <normal_map>materials/textures/Tethys_Normal.png</normal_map>
              <metalness_map>materials/textures/Tethys_Metalness.png</metalness_map>
              <roughness_map>materials/textures/Tethys_Roughness.png</roughness_map>
            </metal>
          </pbr>
        </material>
      </visual>
    </link>
    <!-- Joints -->
    <joint name="horizontal_fins_joint" type="revolute">
      <pose>0 0 0 0 0 0</pose>
      <parent>base_link</parent>
      <child>horizontal_fins</child>
      <axis>
        <xyz>0 1 0</xyz>
        <limit>
          <lower>-0.261799</lower>
          <upper>0.261799</upper>
          <effort>-1</effort>
          <velocity>-1</velocity>
        </limit>
      </axis>
    </joint>
    <joint name="vertical_fins_joint" type="revolute">
      <pose>0 0 0 0 0 0</pose>
      <parent>base_link</parent>
      <child>vertical_fins</child>
      <axis>
        <xyz>0 0 1</xyz>
        <limit>
          <lower>-0.261799</lower>
          <upper>0.261799</upper>
          <effort>-1</effort>
          <velocity>-1</velocity>
        </limit>
      </axis>
    </joint>
    <joint name="propeller_joint" type="revolute">
      <pose>0 0 0 0 0 0</pose>
      <parent>base_link</parent>
      <child>propeller</child>
      <axis>
        <xyz>1 0 0</xyz>
        <limit>
          <lower>-1e+12</lower>
          <upper>1e+12</upper>
          <effort>-1</effort>
          <velocity>-1</velocity>
        </limit>
      </axis>
    </joint>

    <!-- ================= PROPULSION & CONTROL PLUGINS =================
         These were missing from the downloaded model, so cmd_thrust /
         cmd_rudder / cmd_elevator had no effect. Values from the official
         gz-sim8 underwater_vehicles tutorial.
    -->

    <!-- Propeller thrust: converts /model/my_lrauv/joint/propeller_joint/cmd_thrust
         (force in N) into propeller angular velocity. -->
    <plugin filename="gz-sim-thruster-system"
            name="gz::sim::systems::Thruster">
      <namespace>my_lrauv</namespace>
      <use_angvel_cmd>0</use_angvel_cmd>
      <joint_name>propeller_joint</joint_name>
      <thrust_coefficient>0.004422</thrust_coefficient>
      <fluid_density>1000</fluid_density>
      <propeller_diameter>0.2</propeller_diameter>
    </plugin>

    <!-- Hydrodynamic drag/added-mass on the hull. -->
    <plugin filename="gz-sim-hydrodynamics-system"
            name="gz::sim::systems::Hydrodynamics">
      <link_name>base_link</link_name>
      <xUabsU>-6.2282</xUabsU>
      <xU>0</xU>
      <yVabsV>-601.27</yVabsV>
      <yV>0</yV>
      <zWabsW>-601.27</zWabsW>
      <zW>0</zW>
      <kPabsP>-0.1916</kPabsP>
      <kP>0</kP>
      <mQabsQ>-632.698957</mQabsQ>
      <mQ>0</mQ>
      <nRabsR>-632.698957</nRabsR>
      <nR>0</nR>
    </plugin>

    <!-- Vertical fin lift/drag (produces yaw force when rudder is angled). -->
    <plugin filename="gz-sim-lift-drag-system"
            name="gz::sim::systems::LiftDrag">
      <air_density>1000</air_density>
      <cla>4.13</cla>
      <cla_stall>-1.1</cla_stall>
      <cda>0.2</cda>
      <cda_stall>0.03</cda_stall>
      <alpha_stall>0.17</alpha_stall>
      <a0>0</a0>
      <area>0.0244</area>
      <upward>0 1 0</upward>
      <forward>1 0 0</forward>
      <link_name>vertical_fins</link_name>
      <cp>0 0 0</cp>
    </plugin>

    <!-- Horizontal fin lift/drag (produces pitch/dive force when elevator angled). -->
    <plugin filename="gz-sim-lift-drag-system"
            name="gz::sim::systems::LiftDrag">
      <air_density>1000</air_density>
      <cla>4.13</cla>
      <cla_stall>-1.1</cla_stall>
      <cda>0.2</cda>
      <cda_stall>0.03</cda_stall>
      <alpha_stall>0.17</alpha_stall>
      <a0>0</a0>
      <area>0.0244</area>
      <upward>0 0 1</upward>
      <forward>1 0 0</forward>
      <link_name>horizontal_fins</link_name>
      <cp>0 0 0</cp>
    </plugin>

    <!-- Fin position controllers: subscribe to
         /model/my_lrauv/joint/<joint>/0/cmd_pos (the rudder/elevator topics). -->
    <plugin filename="gz-sim-joint-position-controller-system"
            name="gz::sim::systems::JointPositionController">
      <joint_name>horizontal_fins_joint</joint_name>
      <p_gain>0.1</p_gain>
    </plugin>
    <plugin filename="gz-sim-joint-position-controller-system"
            name="gz::sim::systems::JointPositionController">
      <joint_name>vertical_fins_joint</joint_name>
      <p_gain>0.1</p_gain>
    </plugin>

  </model>
</sdf>
